# tests/test_s3sync.py
import pytest
from unittest.mock import patch, MagicMock
import os
# Import functions AFTER patching boto3 if needed, or patch within tests
# from core.s3sync import sync_down, sync_up, BUCKET_NAME

# Since the actual functions currently just 'pass', these tests
# primarily verify they can be called without error and potentially
# check interactions if mocks were involved (e.g., for a real implementation).

# Mock boto3 client at the module level if the module creates the client globally
# If client is created inside functions, patch within each test.
# Assuming s3 = boto3.client("s3") is at module level in s3sync.py
@patch('core.s3sync.boto3.client')
def test_sync_down_runs(mock_boto_client):
    """Test that sync_down can be called."""
    # Configure the mock client if needed
    mock_s3 = MagicMock()
    mock_boto_client.return_value = mock_s3
    # Re-import or reload the module if s3 client is created at import time
    # import importlib
    # import core.s3sync
    # importlib.reload(core.s3sync)
    from core.s3sync import sync_down, BUCKET_NAME

    try:
        sync_down("json/test.json")
        # If sync_down had logic, assert mock_s3.download_file was called
        # mock_s3.download_file.assert_called_once_with(BUCKET_NAME, "json/test.json", "json/test.json")
    except Exception as e:
        pytest.fail(f"sync_down raised an exception: {e}")

@patch('core.s3sync.boto3.client')
def test_sync_up_runs(mock_boto_client):
    """Test that sync_up can be called."""
    mock_s3 = MagicMock()
    mock_boto_client.return_value = mock_s3
    # import importlib
    # import core.s3sync
    # importlib.reload(core.s3sync)
    from core.s3sync import sync_up, BUCKET_NAME

    # Create a dummy file to upload
    dummy_path = "dummy_sync_up.txt"
    with open(dummy_path, "w") as f:
        f.write("test")

    try:
        sync_up(dummy_path)
        # If sync_up had logic, assert mock_s3.upload_file was called
        # mock_s3.upload_file.assert_called_once_with(dummy_path, BUCKET_NAME, dummy_path)
    except Exception as e:
        pytest.fail(f"sync_up raised an exception: {e}")
    finally:
        # Clean up dummy file
        if os.path.exists(dummy_path):
            os.remove(dummy_path)

@patch('core.s3sync.boto3.client')
def test_sync_down_handles_exception(mock_boto_client):
    """Test that sync_down catches exceptions from s3 call."""
    mock_s3 = MagicMock()
    # Simulate an S3 error
    mock_s3.download_file.side_effect = Exception("S3 Download Failed")
    mock_boto_client.return_value = mock_s3
    # import importlib
    # import core.s3sync
    # importlib.reload(core.s3sync)
    from core.s3sync import sync_down

    try:
        # The function should catch the exception and pass
        sync_down("some/path.json")
    except Exception as e:
        pytest.fail(f"sync_down should have caught the exception, but raised: {e}")

@patch('core.s3sync.boto3.client')
def test_sync_up_handles_exception(mock_boto_client):
    """Test that sync_up catches exceptions from s3 call."""
    mock_s3 = MagicMock()
    # Simulate an S3 error
    mock_s3.upload_file.side_effect = Exception("S3 Upload Failed")
    mock_boto_client.return_value = mock_s3
    # import importlib
    # import core.s3sync
    # importlib.reload(core.s3sync)
    from core.s3sync import sync_up

    dummy_path = "dummy_sync_up_fail.txt"
    with open(dummy_path, "w") as f: f.write("test")

    try:
         # The function should catch the exception and pass
        sync_up(dummy_path)
    except Exception as e:
        pytest.fail(f"sync_up should have caught the exception, but raised: {e}")
    finally:
         if os.path.exists(dummy_path): os.remove(dummy_path)